<?xml version="1.0" ?>
<!-- =================================================================================== -->
<!-- |    This document was autogenerated by xacro from /home/user/ros2_ws/src/robo_nemotron_moveit_config/config/robo_nemotron.urdf.xacro | -->
<!-- |    EDITING THIS FILE BY HAND IS NOT RECOMMENDED                                 | -->
<!-- =================================================================================== -->
<robot name="robo_nemotron">
  <link name="world"/>
  <joint name="world_fixed_joint" type="fixed">
    <parent link="world"/>
    <child link="base_link"/>
    <origin rpy="0 0 0" xyz="0 0 0.3"/>
  </joint>
  <link name="base_link">
    <visual>
      <geometry>
        <cylinder length="0.6" radius="0.2"/>
      </geometry>
      <material name="red">
        <color rgba="1.0 0.0 0.0 1.0"/>
      </material>
    </visual>
    <collision>
      <geometry>
        <cylinder length="0.6" radius="0.2"/>
      </geometry>
    </collision>
    <inertial>
      <origin xyz="0 0 0"/>
      <mass value="2.0"/>
      <inertia ixx="0.08" ixy="0.0" ixz="0.0" iyy="0.08" iyz="0.0" izz="0.04"/>
    </inertial>
  </link>
  <link name="link_1">
    <visual>
      <origin xyz="0 0 0.25"/>
      <geometry>
        <cylinder length="0.5" radius="0.1"/>
      </geometry>
      <material name="white">
        <color rgba="1.0 1.0 1.0 1.0"/>
      </material>
    </visual>
    <collision>
      <origin xyz="0 0 0.25"/>
      <geometry>
        <cylinder length="0.5" radius="0.1"/>
      </geometry>
    </collision>
    <inertial>
      <origin xyz="0 0 0.25"/>
      <mass value="1.0"/>
      <inertia ixx="0.023" ixy="0.0" ixz="0.0" iyy="0.023" iyz="0.0" izz="0.005"/>
    </inertial>
  </link>
  <link name="link_2">
    <visual>
      <origin xyz="0 0 0.25"/>
      <geometry>
        <cylinder length="0.5" radius="0.08"/>
      </geometry>
      <material name="red">
        <color rgba="1.0 0.0 0.0 1.0"/>
      </material>
    </visual>
    <collision>
      <origin xyz="0 0 0.25"/>
      <geometry>
        <cylinder length="0.5" radius="0.08"/>
      </geometry>
    </collision>
    <inertial>
      <origin xyz="0 0 0.25"/>
      <mass value="0.8"/>
      <inertia ixx="0.017" ixy="0.0" ixz="0.0" iyy="0.017" iyz="0.0" izz="0.0025"/>
    </inertial>
  </link>
  <link name="link_3">
    <visual>
      <origin xyz="0 0 0.2"/>
      <geometry>
        <cylinder length="0.4" radius="0.06"/>
      </geometry>
      <material name="white">
        <color rgba="1.0 1.0 1.0 1.0"/>
      </material>
    </visual>
    <collision>
      <origin xyz="0 0 0.2"/>
      <geometry>
        <cylinder length="0.4" radius="0.06"/>
      </geometry>
    </collision>
    <inertial>
      <origin xyz="0 0 0.2"/>
      <mass value="0.5"/>
      <inertia ixx="0.007" ixy="0.0" ixz="0.0" iyy="0.007" iyz="0.0" izz="0.0009"/>
    </inertial>
  </link>
  <link name="gripper_base">
    <visual>
      <geometry>
        <box size="0.2 0.05 0.05"/>
      </geometry>
      <material name="yellow">
        <color rgba="1.0 1.0 0.0 1.0"/>
      </material>
    </visual>
    <collision>
      <geometry>
        <box size="0.2 0.05 0.05"/>
      </geometry>
    </collision>
    <inertial>
      <origin xyz="0 0 0"/>
      <mass value="0.3"/>
      <inertia ixx="0.0001" ixy="0.0" ixz="0.0" iyy="0.001" iyz="0.0" izz="0.001"/>
    </inertial>
  </link>
  <link name="left_finger">
    <visual>
      <origin xyz="0 0 0.05"/>
      <geometry>
        <box size="0.02 0.02 0.1"/>
      </geometry>
      <material name="yellow"/>
    </visual>
    <collision>
      <origin xyz="0 0 0.05"/>
      <geometry>
        <box size="0.02 0.02 0.1"/>
      </geometry>
    </collision>
    <inertial>
      <origin xyz="0 0 0.05"/>
      <mass value="0.1"/>
      <inertia ixx="0.00008" ixy="0.0" ixz="0.0" iyy="0.00008" iyz="0.0" izz="0.000006"/>
    </inertial>
  </link>
  <link name="right_finger">
    <visual>
      <origin xyz="0 0 0.05"/>
      <geometry>
        <box size="0.02 0.02 0.1"/>
      </geometry>
      <material name="yellow"/>
    </visual>
    <collision>
      <origin xyz="0 0 0.05"/>
      <geometry>
        <box size="0.02 0.02 0.1"/>
      </geometry>
    </collision>
    <inertial>
      <origin xyz="0 0 0.05"/>
      <mass value="0.1"/>
      <inertia ixx="0.00008" ixy="0.0" ixz="0.0" iyy="0.00008" iyz="0.0" izz="0.000006"/>
    </inertial>
  </link>
  <joint name="arm_0_joint" type="revolute">
    <parent link="base_link"/>
    <child link="link_1"/>
    <origin xyz="0 0 0.3"/>
    <axis xyz="0 0 1"/>
    <limit effort="10" lower="-3.14" upper="3.14" velocity="1.0"/>
  </joint>
  <joint name="arm_1_joint" type="revolute">
    <parent link="link_1"/>
    <child link="link_2"/>
    <origin xyz="0 0 0.5"/>
    <axis xyz="0 1 0"/>
    <limit effort="10" lower="-1.57" upper="1.57" velocity="1.0"/>
  </joint>
  <joint name="arm_2_joint" type="revolute">
    <parent link="link_2"/>
    <child link="link_3"/>
    <origin xyz="0 0 0.5"/>
    <axis xyz="0 1 0"/>
    <limit effort="10" lower="-1.57" upper="1.57" velocity="1.0"/>
  </joint>
  <joint name="gripper_fixed_joint" type="fixed">
    <parent link="link_3"/>
    <child link="gripper_base" safe_child="gripper_base"/>
    <origin rpy="0 0 0" xyz="0 0 0.4"/>
  </joint>
  <joint name="gripper_1_joint" type="prismatic">
    <parent link="gripper_base"/>
    <child link="left_finger"/>
    <origin xyz="-0.08 0 0"/>
    <axis xyz="1 0 0"/>
    <limit effort="5" lower="0.0" upper="0.05" velocity="0.5"/>
  </joint>
  <joint name="gripper_2_joint" type="prismatic">
    <parent link="gripper_base"/>
    <child link="right_finger"/>
    <origin xyz="0.08 0 0"/>
    <axis xyz="-1 0 0"/>
    <limit effort="5" lower="0.0" upper="0.05" velocity="0.5"/>
  </joint>
  <ros2_control name="FakeSystem" type="system">
    <hardware>
      <!-- By default, set up controllers for simulation. This won't work on real hardware -->
      <plugin>gz_ros2_control/GazeboSimSystem</plugin>
    </hardware>
    <joint name="arm_0_joint">
      <command_interface name="position"/>
      <state_interface name="position">
        <param name="initial_value">0</param>
      </state_interface>
      <state_interface name="velocity"/>
    </joint>
    <joint name="arm_1_joint">
      <command_interface name="position"/>
      <state_interface name="position">
        <param name="initial_value">0</param>
      </state_interface>
      <state_interface name="velocity"/>
    </joint>
    <joint name="arm_2_joint">
      <command_interface name="position"/>
      <state_interface name="position">
        <param name="initial_value">0</param>
      </state_interface>
      <state_interface name="velocity"/>
    </joint>
    <joint name="gripper_1_joint">
      <command_interface name="position"/>
      <state_interface name="position">
        <param name="initial_value">0</param>
      </state_interface>
      <state_interface name="velocity"/>
    </joint>
    <joint name="gripper_2_joint">
      <command_interface name="position"/>
      <state_interface name="position">
        <param name="initial_value">0</param>
      </state_interface>
      <state_interface name="velocity"/>
    </joint>
  </ros2_control>
  <gazebo>
    <plugin filename="libgz_ros2_control-system.so" name="gz_ros2_control::GazeboSimROS2ControlPlugin">
      <parameters>/home/user/ros2_ws/install/robo_nemotron_moveit_config/share/robo_nemotron_moveit_config/config/ros2_controllers.yaml</parameters>
      <controller_manager_name>controller_manager</controller_manager_name>
    </plugin>
  </gazebo>
</robot>
